2025-05-27 20:18:02,045 - AkilliEvOtomasyonu - INFO - Akilli Ev Otomasyon Sistemi baslatiliyor
2025-05-27 20:18:02,047 - AkilliEvOtomasyonu - INFO - Veri simülasyonu başlatılıyor
2025-05-27 20:18:02,048 - VeriUretimi - INFO - 3 gün için veri üretiliyor...
2025-05-27 20:18:02,357 - VeriUretimi - INFO - Veri seti C:\Users\ndr20\Desktop\b.tasarım\smart-home-automation\data\raw\generated_data_20250527_2018.csv konumuna kaydedildi.
2025-05-27 20:18:02,358 - AkilliEvOtomasyonu - INFO - Model eğitimi başlatılıyor
2025-05-27 20:18:02,358 - ModelEgitimi - INFO - ML modelleri eğitiliyor: C:\Users\ndr20\Desktop\b.tasarım\smart-home-automation\data\raw\generated_data_20250527_2018.csv
2025-05-27 20:18:09,411 - ErrorHandler - ERROR - Beklenmeyen hata: 
All the 540 fits failed.
It is very likely that your model is misconfigured.
You can try to debug the error by setting error_score='raise'.

Below are more details about the failures:
--------------------------------------------------------------------------------
108 fits failed with the following error:
Traceback (most recent call last):
  File "C:\Users\ndr20\AppData\Roaming\Python\Python313\site-packages\sklearn\model_selection\_validation.py", line 866, in _fit_and_score
    estimator.fit(X_train, y_train, **fit_params)
    ~~~~~~~~~~~~~^^^^^^^^^^^^^^^^^^^^^^^^^^^^^^^^
  File "C:\Users\ndr20\AppData\Roaming\Python\Python313\site-packages\sklearn\base.py", line 1389, in wrapper
    return fit_method(estimator, *args, **kwargs)
  File "C:\Users\ndr20\AppData\Roaming\Python\Python313\site-packages\sklearn\pipeline.py", line 662, in fit
    self._final_estimator.fit(Xt, y, **last_step_params["fit"])
    ~~~~~~~~~~~~~~~~~~~~~~~~~^^^^^^^^^^^^^^^^^^^^^^^^^^^^^^^^^^
  File "C:\Users\ndr20\AppData\Roaming\Python\Python313\site-packages\sklearn\base.py", line 1389, in wrapper
    return fit_method(estimator, *args, **kwargs)
  File "C:\Users\ndr20\AppData\Roaming\Python\Python313\site-packages\sklearn\ensemble\_forest.py", line 360, in fit
    X, y = validate_data(
           ~~~~~~~~~~~~~^
        self,
        ^^^^^
    ...<5 lines>...
        ensure_all_finite=False,
        ^^^^^^^^^^^^^^^^^^^^^^^^
    )
    ^
  File "C:\Users\ndr20\AppData\Roaming\Python\Python313\site-packages\sklearn\utils\validation.py", line 2961, in validate_data
    X, y = check_X_y(X, y, **check_params)
           ~~~~~~~~~^^^^^^^^^^^^^^^^^^^^^^
  File "C:\Users\ndr20\AppData\Roaming\Python\Python313\site-packages\sklearn\utils\validation.py", line 1370, in check_X_y
    X = check_array(
        X,
    ...<12 lines>...
        input_name="X",
    )
  File "C:\Users\ndr20\AppData\Roaming\Python\Python313\site-packages\sklearn\utils\validation.py", line 973, in check_array
    array = array.astype(new_dtype)
  File "C:\Users\ndr20\AppData\Roaming\Python\Python313\site-packages\pandas\core\generic.py", line 6643, in astype
    new_data = self._mgr.astype(dtype=dtype, copy=copy, errors=errors)
  File "C:\Users\ndr20\AppData\Roaming\Python\Python313\site-packages\pandas\core\internals\managers.py", line 430, in astype
    return self.apply(
           ~~~~~~~~~~^
        "astype",
        ^^^^^^^^^
    ...<3 lines>...
        using_cow=using_copy_on_write(),
        ^^^^^^^^^^^^^^^^^^^^^^^^^^^^^^^^
    )
    ^
  File "C:\Users\ndr20\AppData\Roaming\Python\Python313\site-packages\pandas\core\internals\managers.py", line 363, in apply
    applied = getattr(b, f)(**kwargs)
  File "C:\Users\ndr20\AppData\Roaming\Python\Python313\site-packages\pandas\core\internals\blocks.py", line 758, in astype
    new_values = astype_array_safe(values, dtype, copy=copy, errors=errors)
  File "C:\Users\ndr20\AppData\Roaming\Python\Python313\site-packages\pandas\core\dtypes\astype.py", line 237, in astype_array_safe
    new_values = astype_array(values, dtype, copy=copy)
  File "C:\Users\ndr20\AppData\Roaming\Python\Python313\site-packages\pandas\core\dtypes\astype.py", line 182, in astype_array
    values = _astype_nansafe(values, dtype, copy=copy)
  File "C:\Users\ndr20\AppData\Roaming\Python\Python313\site-packages\pandas\core\dtypes\astype.py", line 133, in _astype_nansafe
    return arr.astype(dtype, copy=True)
           ~~~~~~~~~~^^^^^^^^^^^^^^^^^^
ValueError: could not convert string to float: 'Çocuk Odası'

--------------------------------------------------------------------------------
432 fits failed with the following error:
Traceback (most recent call last):
  File "C:\Users\ndr20\AppData\Roaming\Python\Python313\site-packages\sklearn\model_selection\_validation.py", line 866, in _fit_and_score
    estimator.fit(X_train, y_train, **fit_params)
    ~~~~~~~~~~~~~^^^^^^^^^^^^^^^^^^^^^^^^^^^^^^^^
  File "C:\Users\ndr20\AppData\Roaming\Python\Python313\site-packages\sklearn\base.py", line 1389, in wrapper
    return fit_method(estimator, *args, **kwargs)
  File "C:\Users\ndr20\AppData\Roaming\Python\Python313\site-packages\sklearn\pipeline.py", line 662, in fit
    self._final_estimator.fit(Xt, y, **last_step_params["fit"])
    ~~~~~~~~~~~~~~~~~~~~~~~~~^^^^^^^^^^^^^^^^^^^^^^^^^^^^^^^^^^
  File "C:\Users\ndr20\AppData\Roaming\Python\Python313\site-packages\sklearn\base.py", line 1389, in wrapper
    return fit_method(estimator, *args, **kwargs)
  File "C:\Users\ndr20\AppData\Roaming\Python\Python313\site-packages\sklearn\ensemble\_forest.py", line 360, in fit
    X, y = validate_data(
           ~~~~~~~~~~~~~^
        self,
        ^^^^^
    ...<5 lines>...
        ensure_all_finite=False,
        ^^^^^^^^^^^^^^^^^^^^^^^^
    )
    ^
  File "C:\Users\ndr20\AppData\Roaming\Python\Python313\site-packages\sklearn\utils\validation.py", line 2961, in validate_data
    X, y = check_X_y(X, y, **check_params)
           ~~~~~~~~~^^^^^^^^^^^^^^^^^^^^^^
  File "C:\Users\ndr20\AppData\Roaming\Python\Python313\site-packages\sklearn\utils\validation.py", line 1370, in check_X_y
    X = check_array(
        X,
    ...<12 lines>...
        input_name="X",
    )
  File "C:\Users\ndr20\AppData\Roaming\Python\Python313\site-packages\sklearn\utils\validation.py", line 973, in check_array
    array = array.astype(new_dtype)
  File "C:\Users\ndr20\AppData\Roaming\Python\Python313\site-packages\pandas\core\generic.py", line 6643, in astype
    new_data = self._mgr.astype(dtype=dtype, copy=copy, errors=errors)
  File "C:\Users\ndr20\AppData\Roaming\Python\Python313\site-packages\pandas\core\internals\managers.py", line 430, in astype
    return self.apply(
           ~~~~~~~~~~^
        "astype",
        ^^^^^^^^^
    ...<3 lines>...
        using_cow=using_copy_on_write(),
        ^^^^^^^^^^^^^^^^^^^^^^^^^^^^^^^^
    )
    ^
  File "C:\Users\ndr20\AppData\Roaming\Python\Python313\site-packages\pandas\core\internals\managers.py", line 363, in apply
    applied = getattr(b, f)(**kwargs)
  File "C:\Users\ndr20\AppData\Roaming\Python\Python313\site-packages\pandas\core\internals\blocks.py", line 758, in astype
    new_values = astype_array_safe(values, dtype, copy=copy, errors=errors)
  File "C:\Users\ndr20\AppData\Roaming\Python\Python313\site-packages\pandas\core\dtypes\astype.py", line 237, in astype_array_safe
    new_values = astype_array(values, dtype, copy=copy)
  File "C:\Users\ndr20\AppData\Roaming\Python\Python313\site-packages\pandas\core\dtypes\astype.py", line 182, in astype_array
    values = _astype_nansafe(values, dtype, copy=copy)
  File "C:\Users\ndr20\AppData\Roaming\Python\Python313\site-packages\pandas\core\dtypes\astype.py", line 133, in _astype_nansafe
    return arr.astype(dtype, copy=True)
           ~~~~~~~~~~^^^^^^^^^^^^^^^^^^
ValueError: could not convert string to float: 'Salon'
 in train_models
2025-05-27 20:18:09,417 - ErrorHandler - ERROR - Traceback (most recent call last):
  File "C:\Users\ndr20\Desktop\b.tasarım\smart-home-automation\src\utils\error_handling.py", line 65, in wrapper
    return func(*args, **kwargs)
  File "C:\Users\ndr20\Desktop\b.tasarım\smart-home-automation\app.py", line 115, in train_models
    model_manager.train_models_for_all_devices(data_path, model_type='random_forest', optimize=optimize)
    ~~~~~~~~~~~~~~~~~~~~~~~~~~~~~~~~~~~~~~~~~~^^^^^^^^^^^^^^^^^^^^^^^^^^^^^^^^^^^^^^^^^^^^^^^^^^^^^^^^^^
  File "C:\Users\ndr20\Desktop\b.tasarım\smart-home-automation\src\models\model_manager.py", line 55, in train_models_for_all_devices
    model.train(X_train, y_train_dict[device_name], optimize=optimize)
    ~~~~~~~~~~~^^^^^^^^^^^^^^^^^^^^^^^^^^^^^^^^^^^^^^^^^^^^^^^^^^^^^^^
  File "C:\Users\ndr20\Desktop\b.tasarım\smart-home-automation\src\models\model_trainer.py", line 201, in train
    pipeline = self.optimize_hyperparameters(pipeline, X_train, y_train, param_grid)
  File "C:\Users\ndr20\Desktop\b.tasarım\smart-home-automation\src\models\model_trainer.py", line 158, in optimize_hyperparameters
    grid_search.fit(X_train, y_train)
    ~~~~~~~~~~~~~~~^^^^^^^^^^^^^^^^^^
  File "C:\Users\ndr20\AppData\Roaming\Python\Python313\site-packages\sklearn\base.py", line 1389, in wrapper
    return fit_method(estimator, *args, **kwargs)
  File "C:\Users\ndr20\AppData\Roaming\Python\Python313\site-packages\sklearn\model_selection\_search.py", line 1024, in fit
    self._run_search(evaluate_candidates)
    ~~~~~~~~~~~~~~~~^^^^^^^^^^^^^^^^^^^^^
  File "C:\Users\ndr20\AppData\Roaming\Python\Python313\site-packages\sklearn\model_selection\_search.py", line 1571, in _run_search
    evaluate_candidates(ParameterGrid(self.param_grid))
    ~~~~~~~~~~~~~~~~~~~^^^^^^^^^^^^^^^^^^^^^^^^^^^^^^^^
  File "C:\Users\ndr20\AppData\Roaming\Python\Python313\site-packages\sklearn\model_selection\_search.py", line 1001, in evaluate_candidates
    _warn_or_raise_about_fit_failures(out, self.error_score)
    ~~~~~~~~~~~~~~~~~~~~~~~~~~~~~~~~~^^^^^^^^^^^^^^^^^^^^^^^
  File "C:\Users\ndr20\AppData\Roaming\Python\Python313\site-packages\sklearn\model_selection\_validation.py", line 517, in _warn_or_raise_about_fit_failures
    raise ValueError(all_fits_failed_message)
ValueError: 
All the 540 fits failed.
It is very likely that your model is misconfigured.
You can try to debug the error by setting error_score='raise'.

Below are more details about the failures:
--------------------------------------------------------------------------------
108 fits failed with the following error:
Traceback (most recent call last):
  File "C:\Users\ndr20\AppData\Roaming\Python\Python313\site-packages\sklearn\model_selection\_validation.py", line 866, in _fit_and_score
    estimator.fit(X_train, y_train, **fit_params)
    ~~~~~~~~~~~~~^^^^^^^^^^^^^^^^^^^^^^^^^^^^^^^^
  File "C:\Users\ndr20\AppData\Roaming\Python\Python313\site-packages\sklearn\base.py", line 1389, in wrapper
    return fit_method(estimator, *args, **kwargs)
  File "C:\Users\ndr20\AppData\Roaming\Python\Python313\site-packages\sklearn\pipeline.py", line 662, in fit
    self._final_estimator.fit(Xt, y, **last_step_params["fit"])
    ~~~~~~~~~~~~~~~~~~~~~~~~~^^^^^^^^^^^^^^^^^^^^^^^^^^^^^^^^^^
  File "C:\Users\ndr20\AppData\Roaming\Python\Python313\site-packages\sklearn\base.py", line 1389, in wrapper
    return fit_method(estimator, *args, **kwargs)
  File "C:\Users\ndr20\AppData\Roaming\Python\Python313\site-packages\sklearn\ensemble\_forest.py", line 360, in fit
    X, y = validate_data(
           ~~~~~~~~~~~~~^
        self,
        ^^^^^
    ...<5 lines>...
        ensure_all_finite=False,
        ^^^^^^^^^^^^^^^^^^^^^^^^
    )
    ^
  File "C:\Users\ndr20\AppData\Roaming\Python\Python313\site-packages\sklearn\utils\validation.py", line 2961, in validate_data
    X, y = check_X_y(X, y, **check_params)
           ~~~~~~~~~^^^^^^^^^^^^^^^^^^^^^^
  File "C:\Users\ndr20\AppData\Roaming\Python\Python313\site-packages\sklearn\utils\validation.py", line 1370, in check_X_y
    X = check_array(
        X,
    ...<12 lines>...
        input_name="X",
    )
  File "C:\Users\ndr20\AppData\Roaming\Python\Python313\site-packages\sklearn\utils\validation.py", line 973, in check_array
    array = array.astype(new_dtype)
  File "C:\Users\ndr20\AppData\Roaming\Python\Python313\site-packages\pandas\core\generic.py", line 6643, in astype
    new_data = self._mgr.astype(dtype=dtype, copy=copy, errors=errors)
  File "C:\Users\ndr20\AppData\Roaming\Python\Python313\site-packages\pandas\core\internals\managers.py", line 430, in astype
    return self.apply(
           ~~~~~~~~~~^
        "astype",
        ^^^^^^^^^
    ...<3 lines>...
        using_cow=using_copy_on_write(),
        ^^^^^^^^^^^^^^^^^^^^^^^^^^^^^^^^
    )
    ^
  File "C:\Users\ndr20\AppData\Roaming\Python\Python313\site-packages\pandas\core\internals\managers.py", line 363, in apply
    applied = getattr(b, f)(**kwargs)
  File "C:\Users\ndr20\AppData\Roaming\Python\Python313\site-packages\pandas\core\internals\blocks.py", line 758, in astype
    new_values = astype_array_safe(values, dtype, copy=copy, errors=errors)
  File "C:\Users\ndr20\AppData\Roaming\Python\Python313\site-packages\pandas\core\dtypes\astype.py", line 237, in astype_array_safe
    new_values = astype_array(values, dtype, copy=copy)
  File "C:\Users\ndr20\AppData\Roaming\Python\Python313\site-packages\pandas\core\dtypes\astype.py", line 182, in astype_array
    values = _astype_nansafe(values, dtype, copy=copy)
  File "C:\Users\ndr20\AppData\Roaming\Python\Python313\site-packages\pandas\core\dtypes\astype.py", line 133, in _astype_nansafe
    return arr.astype(dtype, copy=True)
           ~~~~~~~~~~^^^^^^^^^^^^^^^^^^
ValueError: could not convert string to float: 'Çocuk Odası'

--------------------------------------------------------------------------------
432 fits failed with the following error:
Traceback (most recent call last):
  File "C:\Users\ndr20\AppData\Roaming\Python\Python313\site-packages\sklearn\model_selection\_validation.py", line 866, in _fit_and_score
    estimator.fit(X_train, y_train, **fit_params)
    ~~~~~~~~~~~~~^^^^^^^^^^^^^^^^^^^^^^^^^^^^^^^^
  File "C:\Users\ndr20\AppData\Roaming\Python\Python313\site-packages\sklearn\base.py", line 1389, in wrapper
    return fit_method(estimator, *args, **kwargs)
  File "C:\Users\ndr20\AppData\Roaming\Python\Python313\site-packages\sklearn\pipeline.py", line 662, in fit
    self._final_estimator.fit(Xt, y, **last_step_params["fit"])
    ~~~~~~~~~~~~~~~~~~~~~~~~~^^^^^^^^^^^^^^^^^^^^^^^^^^^^^^^^^^
  File "C:\Users\ndr20\AppData\Roaming\Python\Python313\site-packages\sklearn\base.py", line 1389, in wrapper
    return fit_method(estimator, *args, **kwargs)
  File "C:\Users\ndr20\AppData\Roaming\Python\Python313\site-packages\sklearn\ensemble\_forest.py", line 360, in fit
    X, y = validate_data(
           ~~~~~~~~~~~~~^
        self,
        ^^^^^
    ...<5 lines>...
        ensure_all_finite=False,
        ^^^^^^^^^^^^^^^^^^^^^^^^
    )
    ^
  File "C:\Users\ndr20\AppData\Roaming\Python\Python313\site-packages\sklearn\utils\validation.py", line 2961, in validate_data
    X, y = check_X_y(X, y, **check_params)
           ~~~~~~~~~^^^^^^^^^^^^^^^^^^^^^^
  File "C:\Users\ndr20\AppData\Roaming\Python\Python313\site-packages\sklearn\utils\validation.py", line 1370, in check_X_y
    X = check_array(
        X,
    ...<12 lines>...
        input_name="X",
    )
  File "C:\Users\ndr20\AppData\Roaming\Python\Python313\site-packages\sklearn\utils\validation.py", line 973, in check_array
    array = array.astype(new_dtype)
  File "C:\Users\ndr20\AppData\Roaming\Python\Python313\site-packages\pandas\core\generic.py", line 6643, in astype
    new_data = self._mgr.astype(dtype=dtype, copy=copy, errors=errors)
  File "C:\Users\ndr20\AppData\Roaming\Python\Python313\site-packages\pandas\core\internals\managers.py", line 430, in astype
    return self.apply(
           ~~~~~~~~~~^
        "astype",
        ^^^^^^^^^
    ...<3 lines>...
        using_cow=using_copy_on_write(),
        ^^^^^^^^^^^^^^^^^^^^^^^^^^^^^^^^
    )
    ^
  File "C:\Users\ndr20\AppData\Roaming\Python\Python313\site-packages\pandas\core\internals\managers.py", line 363, in apply
    applied = getattr(b, f)(**kwargs)
  File "C:\Users\ndr20\AppData\Roaming\Python\Python313\site-packages\pandas\core\internals\blocks.py", line 758, in astype
    new_values = astype_array_safe(values, dtype, copy=copy, errors=errors)
  File "C:\Users\ndr20\AppData\Roaming\Python\Python313\site-packages\pandas\core\dtypes\astype.py", line 237, in astype_array_safe
    new_values = astype_array(values, dtype, copy=copy)
  File "C:\Users\ndr20\AppData\Roaming\Python\Python313\site-packages\pandas\core\dtypes\astype.py", line 182, in astype_array
    values = _astype_nansafe(values, dtype, copy=copy)
  File "C:\Users\ndr20\AppData\Roaming\Python\Python313\site-packages\pandas\core\dtypes\astype.py", line 133, in _astype_nansafe
    return arr.astype(dtype, copy=True)
           ~~~~~~~~~~^^^^^^^^^^^^^^^^^^
ValueError: could not convert string to float: 'Salon'


2025-05-27 20:18:09,420 - AkilliEvOtomasyonu - ERROR - Uygulama hatası: Beklenmeyen hata: 
All the 540 fits failed.
It is very likely that your model is misconfigured.
You can try to debug the error by setting error_score='raise'.

Below are more details about the failures:
--------------------------------------------------------------------------------
108 fits failed with the following error:
Traceback (most recent call last):
  File "C:\Users\ndr20\AppData\Roaming\Python\Python313\site-packages\sklearn\model_selection\_validation.py", line 866, in _fit_and_score
    estimator.fit(X_train, y_train, **fit_params)
    ~~~~~~~~~~~~~^^^^^^^^^^^^^^^^^^^^^^^^^^^^^^^^
  File "C:\Users\ndr20\AppData\Roaming\Python\Python313\site-packages\sklearn\base.py", line 1389, in wrapper
    return fit_method(estimator, *args, **kwargs)
  File "C:\Users\ndr20\AppData\Roaming\Python\Python313\site-packages\sklearn\pipeline.py", line 662, in fit
    self._final_estimator.fit(Xt, y, **last_step_params["fit"])
    ~~~~~~~~~~~~~~~~~~~~~~~~~^^^^^^^^^^^^^^^^^^^^^^^^^^^^^^^^^^
  File "C:\Users\ndr20\AppData\Roaming\Python\Python313\site-packages\sklearn\base.py", line 1389, in wrapper
    return fit_method(estimator, *args, **kwargs)
  File "C:\Users\ndr20\AppData\Roaming\Python\Python313\site-packages\sklearn\ensemble\_forest.py", line 360, in fit
    X, y = validate_data(
           ~~~~~~~~~~~~~^
        self,
        ^^^^^
    ...<5 lines>...
        ensure_all_finite=False,
        ^^^^^^^^^^^^^^^^^^^^^^^^
    )
    ^
  File "C:\Users\ndr20\AppData\Roaming\Python\Python313\site-packages\sklearn\utils\validation.py", line 2961, in validate_data
    X, y = check_X_y(X, y, **check_params)
           ~~~~~~~~~^^^^^^^^^^^^^^^^^^^^^^
  File "C:\Users\ndr20\AppData\Roaming\Python\Python313\site-packages\sklearn\utils\validation.py", line 1370, in check_X_y
    X = check_array(
        X,
    ...<12 lines>...
        input_name="X",
    )
  File "C:\Users\ndr20\AppData\Roaming\Python\Python313\site-packages\sklearn\utils\validation.py", line 973, in check_array
    array = array.astype(new_dtype)
  File "C:\Users\ndr20\AppData\Roaming\Python\Python313\site-packages\pandas\core\generic.py", line 6643, in astype
    new_data = self._mgr.astype(dtype=dtype, copy=copy, errors=errors)
  File "C:\Users\ndr20\AppData\Roaming\Python\Python313\site-packages\pandas\core\internals\managers.py", line 430, in astype
    return self.apply(
           ~~~~~~~~~~^
        "astype",
        ^^^^^^^^^
    ...<3 lines>...
        using_cow=using_copy_on_write(),
        ^^^^^^^^^^^^^^^^^^^^^^^^^^^^^^^^
    )
    ^
  File "C:\Users\ndr20\AppData\Roaming\Python\Python313\site-packages\pandas\core\internals\managers.py", line 363, in apply
    applied = getattr(b, f)(**kwargs)
  File "C:\Users\ndr20\AppData\Roaming\Python\Python313\site-packages\pandas\core\internals\blocks.py", line 758, in astype
    new_values = astype_array_safe(values, dtype, copy=copy, errors=errors)
  File "C:\Users\ndr20\AppData\Roaming\Python\Python313\site-packages\pandas\core\dtypes\astype.py", line 237, in astype_array_safe
    new_values = astype_array(values, dtype, copy=copy)
  File "C:\Users\ndr20\AppData\Roaming\Python\Python313\site-packages\pandas\core\dtypes\astype.py", line 182, in astype_array
    values = _astype_nansafe(values, dtype, copy=copy)
  File "C:\Users\ndr20\AppData\Roaming\Python\Python313\site-packages\pandas\core\dtypes\astype.py", line 133, in _astype_nansafe
    return arr.astype(dtype, copy=True)
           ~~~~~~~~~~^^^^^^^^^^^^^^^^^^
ValueError: could not convert string to float: 'Çocuk Odası'

--------------------------------------------------------------------------------
432 fits failed with the following error:
Traceback (most recent call last):
  File "C:\Users\ndr20\AppData\Roaming\Python\Python313\site-packages\sklearn\model_selection\_validation.py", line 866, in _fit_and_score
    estimator.fit(X_train, y_train, **fit_params)
    ~~~~~~~~~~~~~^^^^^^^^^^^^^^^^^^^^^^^^^^^^^^^^
  File "C:\Users\ndr20\AppData\Roaming\Python\Python313\site-packages\sklearn\base.py", line 1389, in wrapper
    return fit_method(estimator, *args, **kwargs)
  File "C:\Users\ndr20\AppData\Roaming\Python\Python313\site-packages\sklearn\pipeline.py", line 662, in fit
    self._final_estimator.fit(Xt, y, **last_step_params["fit"])
    ~~~~~~~~~~~~~~~~~~~~~~~~~^^^^^^^^^^^^^^^^^^^^^^^^^^^^^^^^^^
  File "C:\Users\ndr20\AppData\Roaming\Python\Python313\site-packages\sklearn\base.py", line 1389, in wrapper
    return fit_method(estimator, *args, **kwargs)
  File "C:\Users\ndr20\AppData\Roaming\Python\Python313\site-packages\sklearn\ensemble\_forest.py", line 360, in fit
    X, y = validate_data(
           ~~~~~~~~~~~~~^
        self,
        ^^^^^
    ...<5 lines>...
        ensure_all_finite=False,
        ^^^^^^^^^^^^^^^^^^^^^^^^
    )
    ^
  File "C:\Users\ndr20\AppData\Roaming\Python\Python313\site-packages\sklearn\utils\validation.py", line 2961, in validate_data
    X, y = check_X_y(X, y, **check_params)
           ~~~~~~~~~^^^^^^^^^^^^^^^^^^^^^^
  File "C:\Users\ndr20\AppData\Roaming\Python\Python313\site-packages\sklearn\utils\validation.py", line 1370, in check_X_y
    X = check_array(
        X,
    ...<12 lines>...
        input_name="X",
    )
  File "C:\Users\ndr20\AppData\Roaming\Python\Python313\site-packages\sklearn\utils\validation.py", line 973, in check_array
    array = array.astype(new_dtype)
  File "C:\Users\ndr20\AppData\Roaming\Python\Python313\site-packages\pandas\core\generic.py", line 6643, in astype
    new_data = self._mgr.astype(dtype=dtype, copy=copy, errors=errors)
  File "C:\Users\ndr20\AppData\Roaming\Python\Python313\site-packages\pandas\core\internals\managers.py", line 430, in astype
    return self.apply(
           ~~~~~~~~~~^
        "astype",
        ^^^^^^^^^
    ...<3 lines>...
        using_cow=using_copy_on_write(),
        ^^^^^^^^^^^^^^^^^^^^^^^^^^^^^^^^
    )
    ^
  File "C:\Users\ndr20\AppData\Roaming\Python\Python313\site-packages\pandas\core\internals\managers.py", line 363, in apply
    applied = getattr(b, f)(**kwargs)
  File "C:\Users\ndr20\AppData\Roaming\Python\Python313\site-packages\pandas\core\internals\blocks.py", line 758, in astype
    new_values = astype_array_safe(values, dtype, copy=copy, errors=errors)
  File "C:\Users\ndr20\AppData\Roaming\Python\Python313\site-packages\pandas\core\dtypes\astype.py", line 237, in astype_array_safe
    new_values = astype_array(values, dtype, copy=copy)
  File "C:\Users\ndr20\AppData\Roaming\Python\Python313\site-packages\pandas\core\dtypes\astype.py", line 182, in astype_array
    values = _astype_nansafe(values, dtype, copy=copy)
  File "C:\Users\ndr20\AppData\Roaming\Python\Python313\site-packages\pandas\core\dtypes\astype.py", line 133, in _astype_nansafe
    return arr.astype(dtype, copy=True)
           ~~~~~~~~~~^^^^^^^^^^^^^^^^^^
ValueError: could not convert string to float: 'Salon'

